#VRML_SIM R2025a utf8

EXTERNPROTO "https://raw.githubusercontent.com/cyberbotics/webots/R2025a/projects/objects/backgrounds/protos/TexturedBackground.proto"
EXTERNPROTO "https://raw.githubusercontent.com/cyberbotics/webots/R2025a/projects/objects/backgrounds/protos/TexturedBackgroundLight.proto"
EXTERNPROTO "https://raw.githubusercontent.com/cyberbotics/webots/R2025a/projects/objects/floors/protos/RectangleArena.proto"
EXTERNPROTO "https://raw.githubusercontent.com/cyberbotics/webots/R2025a/projects/objects/kitchen/breakfast/protos/CerealBox.proto"
EXTERNPROTO "https://raw.githubusercontent.com/cyberbotics/webots/R2025a/projects/objects/toys/protos/RubberDuck.proto"
EXTERNPROTO "https://raw.githubusercontent.com/cyberbotics/webots/R2025a/projects/objects/apartment_structure/protos/Wall.proto"
EXTERNPROTO "https://raw.githubusercontent.com/cyberbotics/webots/R2025a/projects/objects/balls/protos/FifaSoccerBall.proto"
EXTERNPROTO "https://raw.githubusercontent.com/cyberbotics/webots/R2025a/projects/objects/computers/protos/DesktopComputer.proto"

WorldInfo {
}
Viewpoint {
  orientation -0.5445944874456705 -0.5068316676355776 0.6682353664133069 4.234638185501069
  position -2.2138767855146013 4.365077299861805 7.137863042304521
}
TexturedBackground {
}
TexturedBackgroundLight {
}
RectangleArena {
  floorSize 10 10
}
CerealBox {
  translation 3.14 -5.947820934588816e-18 -0.00039239999963314176
  rotation 0.9317404785237169 0.3350657322491895 0.1399665522641372 8.447231185395802e-17
}
DEF rover Robot {
  translation -2.9 4.3 0.0929565
  rotation 0.001182871205183983 0.0007868802467954813 -0.9999989908170854 1.5707994551204272
  children [
    Camera {
      translation 0.29 -0.1 0.1
      children [
        DEF cambox Shape {
          appearance PBRAppearance {
          }
          geometry Box {
            size 0.1 0.1 0.1
          }
        }
      ]
      name "CAM"
      boundingObject USE cambox
      physics Physics {
      }
      width 640
      height 480
      recognition Recognition {
      }
    }
    DEF ds_left DistanceSensor {
      translation 0.36 0.1 0
      rotation 0 0 1 0.3927
      children [
        DEF sensor Shape {
          appearance PBRAppearance {
            baseColor 1 0.196078 0.0901961
          }
          geometry Box {
            size 0.025 0.025 0.025
          }
        }
      ]
      name "ds_left"
      boundingObject USE sensor
      physics Physics {
      }
      lookupTable [
        0 0 0
        0.4 1000 0
      ]
      numberOfRays 2
      resolution 1024
    }
    DEF ds_right DistanceSensor {
      translation 0.36 -0.1 0
      rotation 0 0 1 -0.3927
      children [
        DEF sensor Shape {
          appearance PBRAppearance {
            baseColor 1 0.196078 0.0901961
          }
          geometry Box {
            size 0.025 0.025 0.025
          }
        }
      ]
      name "ds_right"
      boundingObject USE sensor
      physics Physics {
      }
      lookupTable [
        0 0 0
        0.4 1000 0
      ]
      numberOfRays 2
    }
    DEF body Shape {
      appearance PBRAppearance {
        baseColor 0.3 0.3 0.3
        metalness 0
      }
      geometry Box {
        size 0.7 0.4 0.1
      }
    }
    HingeJoint {
      jointParameters HingeJointParameters {
        position -2.2392175337052157e-08
        axis 0 1 0
        anchor 0.175 0.225 0
      }
      device [
        RotationalMotor {
          name "wheel1"
        }
      ]
      endPoint Solid {
        translation 0.175 0.225 0
        rotation 0.9999999999999997 -1.1196049342154448e-08 1.1196087747030564e-08 1.5707996938995756
        children [
          DEF wheel Shape {
            appearance PBRAppearance {
              baseColor 0.6 0.552941 0.47451
              metalness 0
            }
            geometry Cylinder {
              height 0.05
              radius 0.1
            }
          }
        ]
        boundingObject USE wheel
        physics DEF Physics_wh Physics {
        }
      }
    }
    HingeJoint {
      jointParameters HingeJointParameters {
        position -7.561428237272522e-09
        axis 0 1 0
        anchor 0.175 -0.225 0
      }
      device [
        RotationalMotor {
          name "wheel2"
        }
      ]
      endPoint Solid {
        translation 0.175 -0.225 0
        rotation 1 -3.780701270840766e-09 3.780714197140752e-09 1.5707996938995734
        children [
          DEF wheel Shape {
            appearance PBRAppearance {
              baseColor 0.6 0.552941 0.47451
              metalness 0
            }
            geometry Cylinder {
              height 0.05
              radius 0.1
            }
          }
        ]
        name "solid(1)"
        boundingObject USE wheel
        physics DEF Physics_wh Physics {
        }
      }
    }
    HingeJoint {
      jointParameters HingeJointParameters {
        position 2.3310075592919605e-08
        axis 0 1 0
        anchor -0.175 0.225 0
      }
      device [
        RotationalMotor {
          name "wheel3"
        }
      ]
      endPoint Solid {
        translation -0.175 0.225 0
        rotation 0.9999999999999997 1.1654998709802592e-08 -1.1655037953468779e-08 1.570799693899572
        children [
          DEF wheel Shape {
            appearance PBRAppearance {
              baseColor 0.6 0.552941 0.47451
              metalness 0
            }
            geometry Cylinder {
              height 0.05
              radius 0.1
            }
          }
        ]
        name "solid(2)"
        boundingObject USE wheel
        physics DEF Physics_wh Physics {
        }
      }
    }
    HingeJoint {
      jointParameters HingeJointParameters {
        position -2.8061402110024214e-08
        axis 0 1 0
        anchor -0.175 -0.225 0
      }
      device [
        RotationalMotor {
          name "wheel4"
        }
      ]
      endPoint Solid {
        translation -0.175 -0.225 0
        rotation 0.9999999999999997 -1.403065322346886e-08 1.403070109426435e-08 1.5707996938995712
        children [
          DEF wheel Shape {
            appearance PBRAppearance {
              baseColor 0.6 0.552941 0.47451
              metalness 0
            }
            geometry Cylinder {
              height 0.05
              radius 0.1
            }
          }
        ]
        name "solid(3)"
        boundingObject USE wheel
        physics DEF Physics_wh Physics {
        }
      }
    }
    DEF LIDAR_support Shape {
      appearance PBRAppearance {
      }
      geometry Cylinder {
        height 0.5
        radius 0.05
      }
    }
    Lidar {
      translation 0 0 0.24
      children [
        Shape {
          appearance PBRAppearance {
          }
          geometry Cylinder {
            height 0.01
            radius 0.05
          }
        }
      ]
      name "LIDAR"
      numberOfLayers 5
    }
    DEF IMU InertialUnit {
      translation -0.2 0 0.1
      children [
        Shape {
          appearance PBRAppearance {
            baseColor 1 0 1
          }
          geometry Box {
            size 0.1 0.1 0.1
          }
        }
      ]
      name "IMU"
    }
  ]
  boundingObject USE body
  physics Physics {
  }
  controller "OA"
}
RubberDuck {
  translation -5.399230737815218e-08 4.620846815667531e-15 0.059883272260742526
  rotation -8.560546304526628e-08 -0.9999999999999963 -1.237257043073331e-11 8.855206128718803e-07
  scale 3
}
Wall {
  translation 1 0 0
}
Wall {
  translation -4 0 0
  name "wall(1)"
  size 0.2 10 2.4
}
Wall {
  translation -4 -2 0
  rotation 0 0 1 -3.141592653589793
  name "wall(2)"
  size 1.9 0.2 2.3
}
Wall {
  translation 0.7 -4 0
  rotation 0 0 1 -1.1781003061004252
  name "wall(3)"
  size 0.2 3 2.4
}
Wall {
  translation -0.9 -1.7 0
  rotation 0 0 1 0.6545003061004253
  name "wall(4)"
  size 0.2 3 2.4
}
Wall {
  translation -2 2 0
  name "wall(5)"
  size 0.2 5 2.4
}
FifaSoccerBall {
  translation -3.6 1 0.111825
}
Wall {
  translation 2 -2 0
  name "wall(6)"
  size 0.2 3 2.4
}
Wall {
  translation -2 -3 0
  rotation 0 0 1 0.6545003061004253
  name "wall(7)"
  size 0.2 6.1 2.4
}
DesktopComputer {
  translation -1.6 -3 0
}
