#VRML_SIM R2025a utf8

EXTERNPROTO "https://raw.githubusercontent.com/cyberbotics/webots/R2025a/projects/objects/backgrounds/protos/TexturedBackground.proto"
EXTERNPROTO "https://raw.githubusercontent.com/cyberbotics/webots/R2025a/projects/objects/backgrounds/protos/TexturedBackgroundLight.proto"
EXTERNPROTO "https://raw.githubusercontent.com/cyberbotics/webots/R2025a/projects/objects/floors/protos/RectangleArena.proto"
EXTERNPROTO "https://raw.githubusercontent.com/cyberbotics/webots/R2025a/projects/objects/kitchen/breakfast/protos/CerealBox.proto"
EXTERNPROTO "https://raw.githubusercontent.com/cyberbotics/webots/R2025a/projects/objects/apartment_structure/protos/Wall.proto"

WorldInfo {
}
Viewpoint {
  orientation -0.2072554948988892 -0.2005379904745657 0.9575122318856505 4.585229588048168
  position -4.175706882933757 8.992818399018695 3.120200609854774
}
Wall {
  translation -1.04 1.51 0
}
Wall {
  translation -1.97 1.95 0
  rotation 0 0 1 -1.5707953071795862
  name "wall(1)"
  size 0.2 2 2.4
}
Wall {
  translation -4.35 -0.1 0
  name "wall(2)"
  size 0.2 4 2.4
}
Wall {
  translation -0.83 0.43 0
  rotation 0 0 1 1.01503e-06
  name "wall(4)"
}
Wall {
  translation -1.41 -2.01 0
  rotation 0 0 1 1.5708
  name "wall(5)"
  size 0.2 6 2.4
}
Wall {
  translation 1.53 0.87 0
  name "wall(6)"
  size 0.2 6 2.4
}
Wall {
  translation 0.03 2.54 0
  name "wall(7)"
  size 0.2 3 2.4
}
Wall {
  translation -0.46 1.1 0
  rotation 0 0 1 1.5708
  name "wall(8)"
}
TexturedBackground {
}
TexturedBackgroundLight {
}
RectangleArena {
  floorSize 10 10
}
CerealBox {
  translation 3.14 1.2674711179987578e-18 -0.0003923996248258732
  rotation 0.6714428408997084 0.6036484738379108 0.42985233678286555 9.37756931486207e-17
}
DEF rover Robot {
  translation -3.78324 3.89658 0.0993385
  rotation 0.0014810194667551322 0.0007257297386991412 -0.9999986399479179 1.4398996938995747
  children [
    Camera {
      translation 0.29 -0.1 0.1
      children [
        DEF cambox Shape {
          appearance PBRAppearance {
          }
          geometry Box {
            size 0.064 0.048 0.1
          }
        }
      ]
      name "CAM"
      boundingObject USE cambox
      physics Physics {
      }
      width 640
      height 480
      recognition Recognition {
      }
    }
    DEF ds_left DistanceSensor {
      translation 0.36 0.1 0
      rotation 0 0 1 0.3927
      children [
        DEF sensor Shape {
          appearance PBRAppearance {
            baseColor 1 0.196078 0.0901961
          }
          geometry Box {
            size 0.025 0.025 0.025
          }
        }
      ]
      name "ds_left"
      boundingObject USE sensor
      physics Physics {
      }
      lookupTable [
        0 0 0
        0.4 1000 0
      ]
      numberOfRays 2
      resolution 1024
    }
    DEF ds_right DistanceSensor {
      translation 0.36 -0.1 0
      rotation 0 0 1 -0.3927
      children [
        DEF sensor Shape {
          appearance PBRAppearance {
            baseColor 1 0.196078 0.0901961
          }
          geometry Box {
            size 0.025 0.025 0.025
          }
        }
      ]
      name "ds_right"
      boundingObject USE sensor
      physics Physics {
      }
      lookupTable [
        0 0 0
        0.4 1000 0
      ]
      numberOfRays 2
    }
    DEF body Shape {
      appearance PBRAppearance {
        baseColor 0.3 0.3 0.3
        metalness 0
      }
      geometry Box {
        size 0.7 0.4 0.1
      }
    }
    HingeJoint {
      jointParameters HingeJointParameters {
        position -2.151469189604739e-08
        axis 0 1 0
        anchor 0.175 0.225 0
      }
      device [
        RotationalMotor {
          name "wheel1"
        }
      ]
      endPoint Solid {
        translation 0.175 0.225 0
        rotation 0.9999999999999997 -1.0757309589591945e-08 1.0757346046154309e-08 1.5707996938995756
        children [
          DEF wheel Shape {
            appearance PBRAppearance {
              baseColor 0.6 0.552941 0.47451
              metalness 0
            }
            geometry Cylinder {
              height 0.05
              radius 0.1
            }
          }
        ]
        boundingObject USE wheel
        physics DEF Physics_wh Physics {
        }
      }
    }
    HingeJoint {
      jointParameters HingeJointParameters {
        position -8.846462841052885e-09
        axis 0 1 0
        anchor 0.175 -0.225 0
      }
      device [
        RotationalMotor {
          name "wheel2"
        }
      ]
      endPoint Solid {
        translation 0.175 -0.225 0
        rotation 1 -4.423216762581781e-09 4.42323169529216e-09 1.5707996938995747
        children [
          DEF wheel Shape {
            appearance PBRAppearance {
              baseColor 0.6 0.552941 0.47451
              metalness 0
            }
            geometry Cylinder {
              height 0.05
              radius 0.1
            }
          }
        ]
        name "solid(1)"
        boundingObject USE wheel
        physics DEF Physics_wh Physics {
        }
      }
    }
    HingeJoint {
      jointParameters HingeJointParameters {
        position 2.352505651487276e-08
        axis 0 1 0
        anchor -0.175 0.225 0
      }
      device [
        RotationalMotor {
          name "wheel3"
        }
      ]
      endPoint Solid {
        translation -0.175 0.225 0
        rotation 0.9999999999999997 1.1762488612586896e-08 -1.1762528257436379e-08 1.570799693899575
        children [
          DEF wheel Shape {
            appearance PBRAppearance {
              baseColor 0.6 0.552941 0.47451
              metalness 0
            }
            geometry Cylinder {
              height 0.05
              radius 0.1
            }
          }
        ]
        name "solid(2)"
        boundingObject USE wheel
        physics DEF Physics_wh Physics {
        }
      }
    }
    HingeJoint {
      jointParameters HingeJointParameters {
        position -2.8269877787732688e-08
        axis 0 1 0
        anchor -0.175 -0.225 0
      }
      device [
        RotationalMotor {
          name "wheel4"
        }
      ]
      endPoint Solid {
        translation -0.175 -0.225 0
        rotation 0.9999999999999997 -1.413489114311862e-08 1.413493889386634e-08 1.570799693899575
        children [
          DEF wheel Shape {
            appearance PBRAppearance {
              baseColor 0.6 0.552941 0.47451
              metalness 0
            }
            geometry Cylinder {
              height 0.05
              radius 0.1
            }
          }
        ]
        name "solid(3)"
        boundingObject USE wheel
        physics DEF Physics_wh Physics {
        }
      }
    }
    Lidar {
      translation 0 0 0.2
      children [
        Shape {
          appearance PBRAppearance {
          }
          geometry Cylinder {
            height 0.01
            radius 0.05
          }
        }
      ]
      fieldOfView 6.28319
      numberOfLayers 1
      maxRange 5
    }
    DEF IMU InertialUnit {
      translation -0.2 0 0.1
      children [
        Shape {
          appearance PBRAppearance {
            baseColor 1 0 1
          }
          geometry Box {
            size 0.1 0.1 0.1
          }
        }
      ]
      name "IMU"
    }
  ]
  boundingObject USE body
  physics Physics {
  }
  controller "SLAM"
  battery [
    0
  ]
}
